package betterwithmods.common.world.gen.village;

import betterwithmods.common.BWMBlocks;
import betterwithmods.module.hardcore.HCVillages;
import net.minecraft.block.BlockStairs;
import net.minecraft.block.material.Material;
import net.minecraft.block.state.IBlockState;
import net.minecraft.init.Blocks;
import net.minecraft.util.EnumFacing;
import net.minecraft.util.math.MathHelper;
import net.minecraft.world.World;
import net.minecraft.world.gen.structure.StructureBoundingBox;
import net.minecraft.world.gen.structure.StructureComponent;
import net.minecraft.world.gen.structure.StructureVillagePieces;

import java.util.List;
import java.util.Random;

/**
 * Created by tyler on 5/25/17.
 */
public class Butchery extends AbandonedVillagePiece {

    public Butchery() {
    }

    public Butchery(StructureVillagePieces.Start start, int type, Random rand, StructureBoundingBox p_i45567_4_, EnumFacing facing) {
        super(start, type);
        this.setCoordBaseMode(facing);
        this.boundingBox = p_i45567_4_;
    }

    @Override
    public StructureVillagePieces.PieceWeight getVillagePieceWeight(Random random, int size) {
        return new StructureVillagePieces.PieceWeight(Butchery.class, 15, MathHelper.getInt(random, 0 + size, 2 + size));
    }

    @Override
    public Class<?> getComponentClass() {
        return Butchery.class;
    }

    @Override
    public StructureVillagePieces.Village buildComponent(StructureVillagePieces.PieceWeight villagePiece, StructureVillagePieces.Start startPiece, List<StructureComponent> pieces, Random random, int p1, int p2, int p3, EnumFacing facing, int p5) {
        StructureBoundingBox structureboundingbox = StructureBoundingBox.getComponentToAddBoundingBox(p1, p2, p3, 0, 0, 0, 9, 7, 11, facing);
        return canVillageGoDeeper(structureboundingbox) && StructureComponent.findIntersecting(pieces, structureboundingbox) == null ? new Butchery(startPiece, p5, random, structureboundingbox, facing) : null;
    }

    public boolean addComponentParts(World worldIn, Random randomIn, StructureBoundingBox structureBoundingBoxIn) {
        if (this.averageGroundLvl < 0) {
            this.averageGroundLvl = this.getAverageGroundLevel(worldIn, structureBoundingBoxIn);

            if (this.averageGroundLvl < 0) {
                return true;
            }

            this.boundingBox.offset(0, this.averageGroundLvl - this.boundingBox.maxY + 7 - 1, 0);
        }
        IBlockState table = this.getBiomeSpecificBlockState(BWMBlocks.WOOD_TABLE.getDefaultState());
        IBlockState iblockstate = this.getBiomeSpecificBlockState(Blocks.COBBLESTONE.getDefaultState());
        IBlockState iblockstate1 = this.getBiomeSpecificBlockState(Blocks.OAK_STAIRS.getDefaultState().withProperty(BlockStairs.FACING, EnumFacing.NORTH));
        IBlockState iblockstate2 = this.getBiomeSpecificBlockState(Blocks.OAK_STAIRS.getDefaultState().withProperty(BlockStairs.FACING, EnumFacing.SOUTH));
        IBlockState iblockstate3 = this.getBiomeSpecificBlockState(Blocks.OAK_STAIRS.getDefaultState().withProperty(BlockStairs.FACING, EnumFacing.WEST));
        IBlockState iblockstate4 = this.getBiomeSpecificBlockState(Blocks.PLANKS.getDefaultState());
        IBlockState iblockstate5 = this.getBiomeSpecificBlockState(Blocks.LOG.getDefaultState());
        IBlockState fence = this.getBiomeSpecificBlockState(Blocks.OAK_FENCE.getDefaultState());
        IBlockState stoneslab = Blocks.DOUBLE_STONE_SLAB.getDefaultState();

        IBlockState iblockstate7 = iblockstate1;
        IBlockState iblockstate8 = iblockstate2;
        if (HCVillages.disableAllComplexBlocks) {
            table = Blocks.AIR.getDefaultState();
            iblockstate1 = iblockstate4;
            iblockstate2 = iblockstate4;
            iblockstate3 = iblockstate4;
            fence = Blocks.AIR.getDefaultState();
            stoneslab = iblockstate;
        }
        this.fillWithBlocks(worldIn, structureBoundingBoxIn, 1, 1, 1, 7, 4, 4, Blocks.AIR.getDefaultState(), Blocks.AIR.getDefaultState(), false);
        this.fillWithBlocks(worldIn, structureBoundingBoxIn, 2, 1, 6, 8, 4, 10, Blocks.AIR.getDefaultState(), Blocks.AIR.getDefaultState(), false);
        this.fillWithBlocks(worldIn, structureBoundingBoxIn, 2, 0, 6, 8, 0, 10, Blocks.DIRT.getDefaultState(), Blocks.DIRT.getDefaultState(), false);
        this.setBlockState(worldIn, iblockstate, 6, 0, 6, structureBoundingBoxIn);
        this.fillWithBlocks(worldIn, structureBoundingBoxIn, 2, 1, 6, 2, 1, 10, fence, fence, false);
        this.fillWithBlocks(worldIn, structureBoundingBoxIn, 8, 1, 6, 8, 1, 10, fence, fence, false);
        this.fillWithBlocks(worldIn, structureBoundingBoxIn, 3, 1, 10, 7, 1, 10, fence, fence, false);
        this.fillWithBlocks(worldIn, structureBoundingBoxIn, 1, 0, 1, 7, 0, 4, iblockstate4, iblockstate4, false);
        this.fillWithBlocks(worldIn, structureBoundingBoxIn, 0, 0, 0, 0, 3, 5, iblockstate, iblockstate, false);
        this.fillWithBlocks(worldIn, structureBoundingBoxIn, 8, 0, 0, 8, 3, 5, iblockstate, iblockstate, false);
        this.fillWithBlocks(worldIn, structureBoundingBoxIn, 1, 0, 0, 7, 1, 0, iblockstate, iblockstate, false);
        this.fillWithBlocks(worldIn, structureBoundingBoxIn, 1, 0, 5, 7, 1, 5, iblockstate, iblockstate, false);
        this.fillWithBlocks(worldIn, structureBoundingBoxIn, 1, 2, 0, 7, 3, 0, iblockstate4, iblockstate4, false);
        this.fillWithBlocks(worldIn, structureBoundingBoxIn, 1, 2, 5, 7, 3, 5, iblockstate4, iblockstate4, false);
        this.fillWithBlocks(worldIn, structureBoundingBoxIn, 0, 4, 1, 8, 4, 1, iblockstate4, iblockstate4, false);
        this.fillWithBlocks(worldIn, structureBoundingBoxIn, 0, 4, 4, 8, 4, 4, iblockstate4, iblockstate4, false);
        this.fillWithBlocks(worldIn, structureBoundingBoxIn, 0, 5, 2, 8, 5, 3, iblockstate4, iblockstate4, false);
        this.setBlockState(worldIn, iblockstate4, 0, 4, 2, structureBoundingBoxIn);
        this.setBlockState(worldIn, iblockstate4, 0, 4, 3, structureBoundingBoxIn);
        this.setBlockState(worldIn, iblockstate4, 8, 4, 2, structureBoundingBoxIn);
        this.setBlockState(worldIn, iblockstate4, 8, 4, 3, structureBoundingBoxIn);


        for (int i = -1; i <= 2; ++i) {
            for (int j = 0; j <= 8; ++j) {
                this.setBlockState(worldIn, iblockstate7, j, 4 + i, i, structureBoundingBoxIn);
                this.setBlockState(worldIn, iblockstate8, j, 4 + i, 5 - i, structureBoundingBoxIn);
            }
        }

        this.setBlockState(worldIn, iblockstate5, 0, 2, 1, structureBoundingBoxIn);
        this.setBlockState(worldIn, iblockstate5, 0, 2, 4, structureBoundingBoxIn);
        this.setBlockState(worldIn, iblockstate5, 8, 2, 1, structureBoundingBoxIn);
        this.setBlockState(worldIn, iblockstate5, 8, 2, 4, structureBoundingBoxIn);
        this.setBlockState(worldIn, Blocks.AIR.getDefaultState(), 0, 2, 2, structureBoundingBoxIn);
        this.setBlockState(worldIn, Blocks.AIR.getDefaultState(), 0, 2, 3, structureBoundingBoxIn);
        this.setBlockState(worldIn, Blocks.AIR.getDefaultState(), 8, 2, 2, structureBoundingBoxIn);
        this.setBlockState(worldIn, Blocks.AIR.getDefaultState(), 8, 2, 3, structureBoundingBoxIn);
        this.setBlockState(worldIn, Blocks.AIR.getDefaultState(), 2, 2, 5, structureBoundingBoxIn);
        this.setBlockState(worldIn, Blocks.AIR.getDefaultState(), 3, 2, 5, structureBoundingBoxIn);
        this.setBlockState(worldIn, Blocks.AIR.getDefaultState(), 5, 2, 0, structureBoundingBoxIn);
        this.setBlockState(worldIn, Blocks.AIR.getDefaultState(), 6, 2, 5, structureBoundingBoxIn);
        this.setBlockState(worldIn, table, 2, 1, 3, structureBoundingBoxIn);
        this.setBlockState(worldIn, iblockstate4, 1, 1, 4, structureBoundingBoxIn);
        this.setBlockState(worldIn, iblockstate7, 2, 1, 4, structureBoundingBoxIn);
        this.setBlockState(worldIn, iblockstate3, 1, 1, 3, structureBoundingBoxIn);

        this.fillWithBlocks(worldIn, structureBoundingBoxIn, 5, 0, 1, 7, 0, 3, stoneslab, stoneslab, false);
        this.setBlockState(worldIn, stoneslab, 6, 1, 1, structureBoundingBoxIn);
        this.setBlockState(worldIn, stoneslab, 6, 1, 2, structureBoundingBoxIn);
        this.setBlockState(worldIn, Blocks.AIR.getDefaultState(), 2, 1, 0, structureBoundingBoxIn);
        this.setBlockState(worldIn, Blocks.AIR.getDefaultState(), 2, 2, 0, structureBoundingBoxIn);
        this.placeTorch(worldIn, EnumFacing.NORTH, 2, 3, 1, structureBoundingBoxIn);

        if (this.getBlockStateFromPos(worldIn, 2, 0, -1, structureBoundingBoxIn).getMaterial() == Material.AIR && this.getBlockStateFromPos(worldIn, 2, -1, -1, structureBoundingBoxIn).getMaterial() != Material.AIR) {
            this.setBlockState(worldIn, iblockstate7, 2, 0, -1, structureBoundingBoxIn);

            if (this.getBlockStateFromPos(worldIn, 2, -1, -1, structureBoundingBoxIn).getBlock() == Blocks.GRASS_PATH) {
                this.setBlockState(worldIn, Blocks.GRASS.getDefaultState(), 2, -1, -1, structureBoundingBoxIn);
            }
        }

        this.setBlockState(worldIn, Blocks.AIR.getDefaultState(), 6, 1, 5, structureBoundingBoxIn);
        this.setBlockState(worldIn, Blocks.AIR.getDefaultState(), 6, 2, 5, structureBoundingBoxIn);
        this.placeTorch(worldIn, EnumFacing.SOUTH, 6, 3, 4, structureBoundingBoxIn);

        for (int k = 0; k < 5; ++k) {
            for (int l = 0; l < 9; ++l) {
                this.clearCurrentPositionBlocksUpwards(worldIn, l, 7, k, structureBoundingBoxIn);
                this.replaceAirAndLiquidDownwards(worldIn, iblockstate, l, -1, k, structureBoundingBoxIn);
            }
        }

        this.spawnVillagers(worldIn, structureBoundingBoxIn, 4, 1, 2, 1);
        return true;
    }

    protected int chooseProfession(int villagersSpawnedIn, int currentVillagerProfession) {
        return 4;
    }
}
