package betterwithmods.common.world.gen.village;

import betterwithmods.common.BWMBlocks;
import betterwithmods.module.hardcore.HCVillages;
import net.minecraft.block.BlockStairs;
import net.minecraft.block.material.Material;
import net.minecraft.block.state.IBlockState;
import net.minecraft.init.Blocks;
import net.minecraft.util.EnumFacing;
import net.minecraft.util.math.MathHelper;
import net.minecraft.world.World;
import net.minecraft.world.gen.structure.StructureBoundingBox;
import net.minecraft.world.gen.structure.StructureComponent;
import net.minecraft.world.gen.structure.StructureVillagePieces;

import java.util.List;
import java.util.Random;

/**
 * Created by tyler on 5/25/17.
 */
public class BWHouse2 extends AbandonedVillagePiece {
    public BWHouse2() {
    }

    public BWHouse2(StructureVillagePieces.Start start, int type, Random rand, StructureBoundingBox p_i45563_4_, EnumFacing facing) {
        super(start, type);
        this.setCoordBaseMode(facing);
        this.boundingBox = p_i45563_4_;
    }


    /**
     * second Part of Structure generating, this for example places Spiderwebs, Mob Spawners, it closes
     * Mineshafts at the end, it adds Fences...
     */
    public boolean addComponentParts(World worldIn, Random randomIn, StructureBoundingBox structureBoundingBoxIn) {
        if (this.averageGroundLvl < 0) {
            this.averageGroundLvl = this.getAverageGroundLevel(worldIn, structureBoundingBoxIn);

            if (this.averageGroundLvl < 0) {
                return true;
            }

            this.boundingBox.offset(0, this.averageGroundLvl - this.boundingBox.maxY + 6 - 1, 0);
        }

        IBlockState table = this.getBiomeSpecificBlockState(BWMBlocks.WOOD_TABLE.getDefaultState());
        IBlockState planks = this.getBiomeSpecificBlockState(Blocks.PLANKS.getDefaultState());
        IBlockState cobblestone = this.getBiomeSpecificBlockState(Blocks.COBBLESTONE.getDefaultState());

        IBlockState iblockstate1 = this.getBiomeSpecificBlockState(Blocks.OAK_STAIRS.getDefaultState().withProperty(BlockStairs.FACING, EnumFacing.NORTH));
        IBlockState iblockstate2 = this.getBiomeSpecificBlockState(Blocks.OAK_STAIRS.getDefaultState().withProperty(BlockStairs.FACING, EnumFacing.WEST));

        IBlockState iblockstate4 = this.getBiomeSpecificBlockState(Blocks.STONE_STAIRS.getDefaultState().withProperty(BlockStairs.FACING, EnumFacing.NORTH));
        IBlockState iblockstate5 = this.getBiomeSpecificBlockState(Blocks.LOG.getDefaultState());
        IBlockState iblockstate6 = this.getBiomeSpecificBlockState(Blocks.OAK_FENCE.getDefaultState());

        IBlockState iblockstate7 = Blocks.DOUBLE_STONE_SLAB.getDefaultState();
        if (HCVillages.disableAllComplexBlocks) {
            iblockstate1 = planks;
            iblockstate2 = planks;
            iblockstate4 = cobblestone;
            iblockstate6 = Blocks.AIR.getDefaultState();
            iblockstate7 = cobblestone;
            table = Blocks.AIR.getDefaultState();
        }
        this.fillWithBlocks(worldIn, structureBoundingBoxIn, 0, 1, 0, 9, 4, 6, Blocks.AIR.getDefaultState(), Blocks.AIR.getDefaultState(), false);
        this.fillWithBlocks(worldIn, structureBoundingBoxIn, 0, 0, 0, 9, 0, 6, cobblestone, cobblestone, false);
        this.fillWithBlocks(worldIn, structureBoundingBoxIn, 0, 4, 0, 9, 4, 6, cobblestone, cobblestone, false);
        this.fillWithBlocks(worldIn, structureBoundingBoxIn, 0, 5, 0, 9, 5, 6, iblockstate7, iblockstate7, false);
        this.fillWithBlocks(worldIn, structureBoundingBoxIn, 1, 5, 1, 8, 5, 5, Blocks.AIR.getDefaultState(), Blocks.AIR.getDefaultState(), false);
        this.fillWithBlocks(worldIn, structureBoundingBoxIn, 1, 1, 0, 2, 3, 0, planks, planks, false);
        this.fillWithBlocks(worldIn, structureBoundingBoxIn, 0, 1, 0, 0, 4, 0, iblockstate5, iblockstate5, false);
        this.fillWithBlocks(worldIn, structureBoundingBoxIn, 3, 1, 0, 3, 4, 0, iblockstate5, iblockstate5, false);
        this.fillWithBlocks(worldIn, structureBoundingBoxIn, 0, 1, 6, 0, 4, 6, iblockstate5, iblockstate5, false);
        this.setBlockState(worldIn, planks, 3, 3, 1, structureBoundingBoxIn);
        this.fillWithBlocks(worldIn, structureBoundingBoxIn, 3, 1, 2, 3, 3, 2, planks, planks, false);
        this.fillWithBlocks(worldIn, structureBoundingBoxIn, 4, 1, 3, 5, 3, 3, planks, planks, false);
        this.fillWithBlocks(worldIn, structureBoundingBoxIn, 0, 1, 1, 0, 3, 5, planks, planks, false);
        this.fillWithBlocks(worldIn, structureBoundingBoxIn, 1, 1, 6, 5, 3, 6, planks, planks, false);
        this.fillWithBlocks(worldIn, structureBoundingBoxIn, 5, 1, 0, 5, 3, 0, iblockstate6, iblockstate6, false);
        this.fillWithBlocks(worldIn, structureBoundingBoxIn, 9, 1, 0, 9, 3, 0, iblockstate6, iblockstate6, false);
        this.fillWithBlocks(worldIn, structureBoundingBoxIn, 6, 1, 4, 9, 4, 6, cobblestone, cobblestone, false);
        this.setBlockState(worldIn, Blocks.AIR.getDefaultState(), 7, 1, 5, structureBoundingBoxIn);
        this.setBlockState(worldIn, Blocks.AIR.getDefaultState(), 8, 1, 5, structureBoundingBoxIn);
        this.setBlockState(worldIn, Blocks.AIR.getDefaultState(), 9, 2, 5, structureBoundingBoxIn);
        this.setBlockState(worldIn, Blocks.AIR.getDefaultState(), 9, 2, 4, structureBoundingBoxIn);
//        this.setBlockState(worldIn, Blocks.FLOWING_LAVA.getDefaultState(), 7, 1, 5, structureBoundingBoxIn);
//        this.setBlockState(worldIn, Blocks.FLOWING_LAVA.getDefaultState(), 8, 1, 5, structureBoundingBoxIn);
//        this.setBlockState(worldIn, Blocks.IRON_BARS.getDefaultState(), 9, 2, 5, structureBoundingBoxIn);
//        this.setBlockState(worldIn, Blocks.IRON_BARS.getDefaultState(), 9, 2, 4, structureBoundingBoxIn);
        this.fillWithBlocks(worldIn, structureBoundingBoxIn, 7, 2, 4, 8, 2, 5, Blocks.AIR.getDefaultState(), Blocks.AIR.getDefaultState(), false);
        this.setBlockState(worldIn, cobblestone, 6, 1, 3, structureBoundingBoxIn);

//        this.setBlockState(worldIn, Blocks.FURNACE.getDefaultState(), 6, 2, 3, structureBoundingBoxIn);
//        this.setBlockState(worldIn, Blocks.FURNACE.getDefaultState(), 6, 3, 3, structureBoundingBoxIn);
        this.setBlockState(worldIn, Blocks.AIR.getDefaultState(), 6, 2, 3, structureBoundingBoxIn);
        this.setBlockState(worldIn, Blocks.AIR.getDefaultState(), 6, 3, 3, structureBoundingBoxIn);

        this.setBlockState(worldIn, iblockstate7, 8, 1, 1, structureBoundingBoxIn);
        this.setBlockState(worldIn, Blocks.AIR.getDefaultState(), 0, 2, 2, structureBoundingBoxIn);
        this.setBlockState(worldIn, Blocks.AIR.getDefaultState(), 0, 2, 4, structureBoundingBoxIn);
        this.setBlockState(worldIn, Blocks.AIR.getDefaultState(), 2, 2, 6, structureBoundingBoxIn);
        this.setBlockState(worldIn, Blocks.AIR.getDefaultState(), 4, 2, 6, structureBoundingBoxIn);
//        this.setBlockState(worldIn, Blocks.GLASS_PANE.getDefaultState(), 0, 2, 2, structureBoundingBoxIn);
//        this.setBlockState(worldIn, Blocks.GLASS_PANE.getDefaultState(), 0, 2, 4, structureBoundingBoxIn);
//        this.setBlockState(worldIn, Blocks.GLASS_PANE.getDefaultState(), 2, 2, 6, structureBoundingBoxIn);
//        this.setBlockState(worldIn, Blocks.GLASS_PANE.getDefaultState(), 4, 2, 6, structureBoundingBoxIn);
//        this.setBlockState(worldIn, iblockstate6, 2, 1, 4, structureBoundingBoxIn);
        this.setBlockState(worldIn, table, 2, 1, 4, structureBoundingBoxIn);
        this.setBlockState(worldIn, Blocks.AIR.getDefaultState(), 2, 2, 4, structureBoundingBoxIn);
        this.setBlockState(worldIn, planks, 1, 1, 5, structureBoundingBoxIn);
        this.setBlockState(worldIn, iblockstate1, 2, 1, 5, structureBoundingBoxIn);
        this.setBlockState(worldIn, iblockstate2, 1, 1, 4, structureBoundingBoxIn);


        for (int i = 6; i <= 8; ++i) {
            if (this.getBlockStateFromPos(worldIn, i, 0, -1, structureBoundingBoxIn).getMaterial() == Material.AIR && this.getBlockStateFromPos(worldIn, i, -1, -1, structureBoundingBoxIn).getMaterial() != Material.AIR) {
                this.setBlockState(worldIn, iblockstate4, i, 0, -1, structureBoundingBoxIn);

                if (this.getBlockStateFromPos(worldIn, i, -1, -1, structureBoundingBoxIn).getBlock() == Blocks.GRASS_PATH) {
                    this.setBlockState(worldIn, Blocks.GRASS.getDefaultState(), i, -1, -1, structureBoundingBoxIn);
                }
            }
        }

        for (int k = 0; k < 7; ++k) {
            for (int j = 0; j < 10; ++j) {
                this.clearCurrentPositionBlocksUpwards(worldIn, j, 6, k, structureBoundingBoxIn);
                this.replaceAirAndLiquidDownwards(worldIn, cobblestone, j, -1, k, structureBoundingBoxIn);
            }
        }

        this.spawnVillagers(worldIn, structureBoundingBoxIn, 7, 1, 1, 1);
        return true;
    }

    protected int chooseProfession(int villagersSpawnedIn, int currentVillagerProfession) {
        return 3;
    }

    @Override
    public StructureVillagePieces.PieceWeight getVillagePieceWeight(Random random, int size) {
        return new StructureVillagePieces.PieceWeight(BWHouse2.class, 15, MathHelper.getInt(random, 0, 1 + size));
    }

    @Override
    public Class<?> getComponentClass() {
        return BWHouse2.class;
    }

    @Override
    public StructureVillagePieces.Village buildComponent(StructureVillagePieces.PieceWeight villagePiece, StructureVillagePieces.Start startPiece, List<StructureComponent> pieces, Random random, int p1, int p2, int p3, EnumFacing facing, int p5) {
        StructureBoundingBox structureboundingbox = StructureBoundingBox.getComponentToAddBoundingBox(p1, p2, p3, 0, 0, 0, 10, 6, 7, facing);
        return canVillageGoDeeper(structureboundingbox) && StructureComponent.findIntersecting(pieces, structureboundingbox) == null ? new BWHouse2(startPiece, p5, random, structureboundingbox, facing) : null;
    }

}