package betterwithmods.common.world.gen.village;

import betterwithmods.common.BWMBlocks;
import net.minecraft.block.BlockStairs;
import net.minecraft.block.material.Material;
import net.minecraft.block.state.IBlockState;
import net.minecraft.init.Blocks;
import net.minecraft.util.EnumFacing;
import net.minecraft.util.math.MathHelper;
import net.minecraft.world.World;
import net.minecraft.world.gen.structure.StructureBoundingBox;
import net.minecraft.world.gen.structure.StructureComponent;
import net.minecraft.world.gen.structure.StructureVillagePieces;

import java.util.List;
import java.util.Random;

/**
 * Created by tyler on 5/25/17.
 */
public class Library extends AbandonedVillagePiece {
    public Library() {
    }

    public Library(StructureVillagePieces.Start start, int type, Random rand, StructureBoundingBox p_i45571_4_, EnumFacing facing) {
        super(start, type);
        this.setCoordBaseMode(facing);
        this.boundingBox = p_i45571_4_;
    }

    /**
     * second Part of Structure generating, this for example places Spiderwebs, Mob Spawners, it closes
     * Mineshafts at the end, it adds Fences...
     */
    public boolean addComponentParts(World worldIn, Random randomIn, StructureBoundingBox structureBoundingBoxIn)
    {
        if (this.averageGroundLvl < 0)
        {
            this.averageGroundLvl = this.getAverageGroundLevel(worldIn, structureBoundingBoxIn);

            if (this.averageGroundLvl < 0)
            {
                return true;
            }

            this.boundingBox.offset(0, this.averageGroundLvl - this.boundingBox.maxY + 9 - 1, 0);
        }
        IBlockState table = this.getBiomeSpecificBlockState(BWMBlocks.WOOD_TABLE.getDefaultState());
        IBlockState window = Blocks.AIR.getDefaultState();
        IBlockState iblockstate = this.getBiomeSpecificBlockState(Blocks.COBBLESTONE.getDefaultState());
        IBlockState iblockstate1 = this.getBiomeSpecificBlockState(Blocks.OAK_STAIRS.getDefaultState().withProperty(BlockStairs.FACING, EnumFacing.NORTH));
        IBlockState iblockstate2 = this.getBiomeSpecificBlockState(Blocks.OAK_STAIRS.getDefaultState().withProperty(BlockStairs.FACING, EnumFacing.SOUTH));
        IBlockState iblockstate3 = this.getBiomeSpecificBlockState(Blocks.OAK_STAIRS.getDefaultState().withProperty(BlockStairs.FACING, EnumFacing.EAST));
        IBlockState iblockstate4 = this.getBiomeSpecificBlockState(Blocks.PLANKS.getDefaultState());
        IBlockState iblockstate5 = this.getBiomeSpecificBlockState(Blocks.STONE_STAIRS.getDefaultState().withProperty(BlockStairs.FACING, EnumFacing.NORTH));
        this.fillWithBlocks(worldIn, structureBoundingBoxIn, 1, 1, 1, 7, 5, 4, Blocks.AIR.getDefaultState(), Blocks.AIR.getDefaultState(), false);
        this.fillWithBlocks(worldIn, structureBoundingBoxIn, 0, 0, 0, 8, 0, 5, iblockstate, iblockstate, false);
        this.fillWithBlocks(worldIn, structureBoundingBoxIn, 0, 5, 0, 8, 5, 5, iblockstate, iblockstate, false);
        this.fillWithBlocks(worldIn, structureBoundingBoxIn, 0, 6, 1, 8, 6, 4, iblockstate, iblockstate, false);
        this.fillWithBlocks(worldIn, structureBoundingBoxIn, 0, 7, 2, 8, 7, 3, iblockstate, iblockstate, false);

        for (int i = -1; i <= 2; ++i)
        {
            for (int j = 0; j <= 8; ++j)
            {
                this.setBlockState(worldIn, iblockstate1, j, 6 + i, i, structureBoundingBoxIn);
                this.setBlockState(worldIn, iblockstate2, j, 6 + i, 5 - i, structureBoundingBoxIn);
            }
        }

        this.fillWithBlocks(worldIn, structureBoundingBoxIn, 0, 1, 0, 0, 1, 5, iblockstate, iblockstate, false);
        this.fillWithBlocks(worldIn, structureBoundingBoxIn, 1, 1, 5, 8, 1, 5, iblockstate, iblockstate, false);
        this.fillWithBlocks(worldIn, structureBoundingBoxIn, 8, 1, 0, 8, 1, 4, iblockstate, iblockstate, false);
        this.fillWithBlocks(worldIn, structureBoundingBoxIn, 2, 1, 0, 7, 1, 0, iblockstate, iblockstate, false);
        this.fillWithBlocks(worldIn, structureBoundingBoxIn, 0, 2, 0, 0, 4, 0, iblockstate, iblockstate, false);
        this.fillWithBlocks(worldIn, structureBoundingBoxIn, 0, 2, 5, 0, 4, 5, iblockstate, iblockstate, false);
        this.fillWithBlocks(worldIn, structureBoundingBoxIn, 8, 2, 5, 8, 4, 5, iblockstate, iblockstate, false);
        this.fillWithBlocks(worldIn, structureBoundingBoxIn, 8, 2, 0, 8, 4, 0, iblockstate, iblockstate, false);
        this.fillWithBlocks(worldIn, structureBoundingBoxIn, 0, 2, 1, 0, 4, 4, iblockstate4, iblockstate4, false);
        this.fillWithBlocks(worldIn, structureBoundingBoxIn, 1, 2, 5, 7, 4, 5, iblockstate4, iblockstate4, false);
        this.fillWithBlocks(worldIn, structureBoundingBoxIn, 8, 2, 1, 8, 4, 4, iblockstate4, iblockstate4, false);
        this.fillWithBlocks(worldIn, structureBoundingBoxIn, 1, 2, 0, 7, 4, 0, iblockstate4, iblockstate4, false);
        this.setBlockState(worldIn, window, 4, 2, 0, structureBoundingBoxIn);
        this.setBlockState(worldIn, window, 5, 2, 0, structureBoundingBoxIn);
        this.setBlockState(worldIn, window, 6, 2, 0, structureBoundingBoxIn);
        this.setBlockState(worldIn, window, 4, 3, 0, structureBoundingBoxIn);
        this.setBlockState(worldIn, window, 5, 3, 0, structureBoundingBoxIn);
        this.setBlockState(worldIn, window, 6, 3, 0, structureBoundingBoxIn);
        this.setBlockState(worldIn, window, 0, 2, 2, structureBoundingBoxIn);
        this.setBlockState(worldIn, window, 0, 2, 3, structureBoundingBoxIn);
        this.setBlockState(worldIn, window, 0, 3, 2, structureBoundingBoxIn);
        this.setBlockState(worldIn, window, 0, 3, 3, structureBoundingBoxIn);
        this.setBlockState(worldIn, window, 8, 2, 2, structureBoundingBoxIn);
        this.setBlockState(worldIn, window, 8, 2, 3, structureBoundingBoxIn);
        this.setBlockState(worldIn, window, 8, 3, 2, structureBoundingBoxIn);
        this.setBlockState(worldIn, window, 8, 3, 3, structureBoundingBoxIn);
        this.setBlockState(worldIn, window, 2, 2, 5, structureBoundingBoxIn);
        this.setBlockState(worldIn, window, 3, 2, 5, structureBoundingBoxIn);
        this.setBlockState(worldIn, window, 5, 2, 5, structureBoundingBoxIn);
        this.setBlockState(worldIn, window, 6, 2, 5, structureBoundingBoxIn);
        this.fillWithBlocks(worldIn, structureBoundingBoxIn, 1, 4, 1, 7, 4, 1, iblockstate4, iblockstate4, false);
        this.fillWithBlocks(worldIn, structureBoundingBoxIn, 1, 4, 4, 7, 4, 4, iblockstate4, iblockstate4, false);
        this.fillWithBlocks(worldIn, structureBoundingBoxIn, 1, 3, 4, 7, 3, 4, Blocks.AIR.getDefaultState(), Blocks.AIR.getDefaultState(), false);
        this.setBlockState(worldIn, iblockstate4, 7, 1, 4, structureBoundingBoxIn);
        this.setBlockState(worldIn, iblockstate3, 7, 1, 3, structureBoundingBoxIn);
        this.setBlockState(worldIn, iblockstate1, 6, 1, 4, structureBoundingBoxIn);
        this.setBlockState(worldIn, iblockstate1, 5, 1, 4, structureBoundingBoxIn);
        this.setBlockState(worldIn, iblockstate1, 4, 1, 4, structureBoundingBoxIn);
        this.setBlockState(worldIn, iblockstate1, 3, 1, 4, structureBoundingBoxIn);

//        this.setBlockState(worldIn, Blocks.WOODEN_PRESSURE_PLATE.getDefaultState(), 6, 2, 3, structureBoundingBoxIn);
        this.setBlockState(worldIn, table, 6, 1, 3, structureBoundingBoxIn);
        this.setBlockState(worldIn, table, 4, 1, 3, structureBoundingBoxIn);
//        this.setBlockState(worldIn, Blocks.WOODEN_PRESSURE_PLATE.getDefaultState(), 4, 2, 3, structureBoundingBoxIn);
//        this.setBlockState(worldIn, Blocks.CRAFTING_TABLE.getDefaultState(), 7, 1, 1, structureBoundingBoxIn);
        this.setBlockState(worldIn, Blocks.AIR.getDefaultState(), 1, 1, 0, structureBoundingBoxIn);
        this.setBlockState(worldIn, Blocks.AIR.getDefaultState(), 1, 2, 0, structureBoundingBoxIn);
//        this.createVillageDoor(worldIn, structureBoundingBoxIn, randomIn, 1, 1, 0, EnumFacing.NORTH);

        if (this.getBlockStateFromPos(worldIn, 1, 0, -1, structureBoundingBoxIn).getMaterial() == Material.AIR && this.getBlockStateFromPos(worldIn, 1, -1, -1, structureBoundingBoxIn).getMaterial() != Material.AIR)
        {
            this.setBlockState(worldIn, iblockstate5, 1, 0, -1, structureBoundingBoxIn);

            if (this.getBlockStateFromPos(worldIn, 1, -1, -1, structureBoundingBoxIn).getBlock() == Blocks.GRASS_PATH)
            {
                this.setBlockState(worldIn, Blocks.GRASS.getDefaultState(), 1, -1, -1, structureBoundingBoxIn);
            }
        }

        for (int l = 0; l < 6; ++l)
        {
            for (int k = 0; k < 9; ++k)
            {
                this.clearCurrentPositionBlocksUpwards(worldIn, k, 9, l, structureBoundingBoxIn);
                this.replaceAirAndLiquidDownwards(worldIn, iblockstate, k, -1, l, structureBoundingBoxIn);
            }
        }

        this.spawnVillagers(worldIn, structureBoundingBoxIn, 2, 1, 2, 1);
        return true;
    }

    protected int chooseProfession(int villagersSpawnedIn, int currentVillagerProfession) {
        return 1;
    }

    @Override
    public StructureVillagePieces.PieceWeight getVillagePieceWeight(Random random, int size) {
        return new StructureVillagePieces.PieceWeight(Library.class, 20, MathHelper.getInt(random, 0 + size, 2 + size));
    }

    @Override
    public Class<?> getComponentClass() {
        return Library.class;
    }

    @Override
    public StructureVillagePieces.Village buildComponent(StructureVillagePieces.PieceWeight villagePiece, StructureVillagePieces.Start startPiece, List<StructureComponent> pieces, Random random, int p1, int p2, int p3, EnumFacing facing, int p5) {
        StructureBoundingBox structureboundingbox = StructureBoundingBox.getComponentToAddBoundingBox(p1, p2, p3, 0, 0, 0, 9, 9, 6, facing);
        return canVillageGoDeeper(structureboundingbox) && StructureComponent.findIntersecting(pieces, structureboundingbox) == null ? new Library(startPiece, p5, random, structureboundingbox, facing) : null;
    }
}